2025-06-26 14:52:14,390 INFO: GPS Tracker startup [in /home/cnhari/gps_tracker_web/app.py:47]
2025-06-26 14:52:19,145 INFO: GPS Tracker startup [in /home/cnhari/gps_tracker_web/app.py:47]
2025-06-26 14:52:40,923 INFO: GPS Tracker startup [in /home/cnhari/gps_tracker_web/app.py:47]
2025-06-26 15:00:47,531 ERROR: Error creating combined chart: Can only use .dt accessor with datetimelike values [in /home/cnhari/gps_tracker_web/app.py:393]
2025-06-26 15:00:47,531 ERROR: Exception on /tracker [POST] [in /home/cnhari/gps_tracker_web/venv/lib/python3.10/site-packages/flask/app.py:875]
Traceback (most recent call last):
  File "/home/cnhari/gps_tracker_web/venv/lib/python3.10/site-packages/flask/app.py", line 1511, in wsgi_app
    response = self.full_dispatch_request()
  File "/home/cnhari/gps_tracker_web/venv/lib/python3.10/site-packages/flask/app.py", line 919, in full_dispatch_request
    rv = self.handle_user_exception(e)
  File "/home/cnhari/gps_tracker_web/venv/lib/python3.10/site-packages/flask/app.py", line 917, in full_dispatch_request
    rv = self.dispatch_request()
  File "/home/cnhari/gps_tracker_web/venv/lib/python3.10/site-packages/flask/app.py", line 902, in dispatch_request
    return self.ensure_sync(self.view_functions[rule.endpoint])(**view_args)  # type: ignore[no-any-return]
  File "/home/cnhari/gps_tracker_web/app.py", line 1118, in tracker
    combined_chart = create_combined_chart(ping_dates, charge_details, full_voltage_df)
  File "/home/cnhari/gps_tracker_web/app.py", line 317, in create_combined_chart
    [charge_dates.dt.year.rename('year'),
  File "/home/cnhari/gps_tracker_web/venv/lib/python3.10/site-packages/pandas/core/generic.py", line 6299, in __getattr__
    return object.__getattribute__(self, name)
  File "/home/cnhari/gps_tracker_web/venv/lib/python3.10/site-packages/pandas/core/accessor.py", line 224, in __get__
    accessor_obj = self._accessor(obj)
  File "/home/cnhari/gps_tracker_web/venv/lib/python3.10/site-packages/pandas/core/indexes/accessors.py", line 643, in __new__
    raise AttributeError("Can only use .dt accessor with datetimelike values")
AttributeError: Can only use .dt accessor with datetimelike values
2025-06-26 15:00:47,532 ERROR: Server Error: 500 Internal Server Error: The server encountered an internal error and was unable to complete your request. Either the server is overloaded or there is an error in the application. [in /home/cnhari/gps_tracker_web/app.py:1183]
2025-06-26 15:30:07,994 INFO: GPS Tracker startup [in /home/cnhari/gps_tracker_web/app.py:47]
2025-06-26 15:35:46,265 ERROR: Error creating combined chart: Can only use .dt accessor with datetimelike values [in /home/cnhari/gps_tracker_web/app.py:403]
2025-06-26 15:35:46,265 ERROR: Exception on /tracker [POST] [in /home/cnhari/gps_tracker_web/venv/lib/python3.10/site-packages/flask/app.py:875]
Traceback (most recent call last):
  File "/home/cnhari/gps_tracker_web/venv/lib/python3.10/site-packages/flask/app.py", line 1511, in wsgi_app
    response = self.full_dispatch_request()
  File "/home/cnhari/gps_tracker_web/venv/lib/python3.10/site-packages/flask/app.py", line 919, in full_dispatch_request
    rv = self.handle_user_exception(e)
  File "/home/cnhari/gps_tracker_web/venv/lib/python3.10/site-packages/flask/app.py", line 917, in full_dispatch_request
    rv = self.dispatch_request()
  File "/home/cnhari/gps_tracker_web/venv/lib/python3.10/site-packages/flask/app.py", line 902, in dispatch_request
    return self.ensure_sync(self.view_functions[rule.endpoint])(**view_args)  # type: ignore[no-any-return]
  File "/home/cnhari/gps_tracker_web/app.py", line 1128, in tracker
    combined_chart = create_combined_chart(ping_dates, charge_details, full_voltage_df)
  File "/home/cnhari/gps_tracker_web/app.py", line 327, in create_combined_chart
    [charge_dates.dt.year.rename('year'),
  File "/home/cnhari/gps_tracker_web/venv/lib/python3.10/site-packages/pandas/core/generic.py", line 6299, in __getattr__
    return object.__getattribute__(self, name)
  File "/home/cnhari/gps_tracker_web/venv/lib/python3.10/site-packages/pandas/core/accessor.py", line 224, in __get__
    accessor_obj = self._accessor(obj)
  File "/home/cnhari/gps_tracker_web/venv/lib/python3.10/site-packages/pandas/core/indexes/accessors.py", line 643, in __new__
    raise AttributeError("Can only use .dt accessor with datetimelike values")
AttributeError: Can only use .dt accessor with datetimelike values
2025-06-26 15:35:46,267 ERROR: Server Error: 500 Internal Server Error: The server encountered an internal error and was unable to complete your request. Either the server is overloaded or there is an error in the application. [in /home/cnhari/gps_tracker_web/app.py:1193]
2025-06-26 15:36:53,648 ERROR: Error creating combined chart: Can only use .dt accessor with datetimelike values [in /home/cnhari/gps_tracker_web/app.py:403]
2025-06-26 15:36:53,648 ERROR: Exception on /tracker [POST] [in /home/cnhari/gps_tracker_web/venv/lib/python3.10/site-packages/flask/app.py:875]
Traceback (most recent call last):
  File "/home/cnhari/gps_tracker_web/venv/lib/python3.10/site-packages/flask/app.py", line 1511, in wsgi_app
    response = self.full_dispatch_request()
  File "/home/cnhari/gps_tracker_web/venv/lib/python3.10/site-packages/flask/app.py", line 919, in full_dispatch_request
    rv = self.handle_user_exception(e)
  File "/home/cnhari/gps_tracker_web/venv/lib/python3.10/site-packages/flask/app.py", line 917, in full_dispatch_request
    rv = self.dispatch_request()
  File "/home/cnhari/gps_tracker_web/venv/lib/python3.10/site-packages/flask/app.py", line 902, in dispatch_request
    return self.ensure_sync(self.view_functions[rule.endpoint])(**view_args)  # type: ignore[no-any-return]
  File "/home/cnhari/gps_tracker_web/app.py", line 1128, in tracker
    combined_chart = create_combined_chart(ping_dates, charge_details, full_voltage_df)
  File "/home/cnhari/gps_tracker_web/app.py", line 327, in create_combined_chart
    [charge_dates.dt.year.rename('year'),
  File "/home/cnhari/gps_tracker_web/venv/lib/python3.10/site-packages/pandas/core/generic.py", line 6299, in __getattr__
    return object.__getattribute__(self, name)
  File "/home/cnhari/gps_tracker_web/venv/lib/python3.10/site-packages/pandas/core/accessor.py", line 224, in __get__
    accessor_obj = self._accessor(obj)
  File "/home/cnhari/gps_tracker_web/venv/lib/python3.10/site-packages/pandas/core/indexes/accessors.py", line 643, in __new__
    raise AttributeError("Can only use .dt accessor with datetimelike values")
AttributeError: Can only use .dt accessor with datetimelike values
2025-06-26 15:36:53,648 ERROR: Server Error: 500 Internal Server Error: The server encountered an internal error and was unable to complete your request. Either the server is overloaded or there is an error in the application. [in /home/cnhari/gps_tracker_web/app.py:1193]
2025-06-26 15:37:50,928 ERROR: Error creating combined chart: Can only use .dt accessor with datetimelike values [in /home/cnhari/gps_tracker_web/app.py:403]
2025-06-26 15:37:50,929 ERROR: Exception on /tracker [POST] [in /home/cnhari/gps_tracker_web/venv/lib/python3.10/site-packages/flask/app.py:875]
Traceback (most recent call last):
  File "/home/cnhari/gps_tracker_web/venv/lib/python3.10/site-packages/flask/app.py", line 1511, in wsgi_app
    response = self.full_dispatch_request()
  File "/home/cnhari/gps_tracker_web/venv/lib/python3.10/site-packages/flask/app.py", line 919, in full_dispatch_request
    rv = self.handle_user_exception(e)
  File "/home/cnhari/gps_tracker_web/venv/lib/python3.10/site-packages/flask/app.py", line 917, in full_dispatch_request
    rv = self.dispatch_request()
  File "/home/cnhari/gps_tracker_web/venv/lib/python3.10/site-packages/flask/app.py", line 902, in dispatch_request
    return self.ensure_sync(self.view_functions[rule.endpoint])(**view_args)  # type: ignore[no-any-return]
  File "/home/cnhari/gps_tracker_web/app.py", line 1128, in tracker
    combined_chart = create_combined_chart(ping_dates, charge_details, full_voltage_df)
  File "/home/cnhari/gps_tracker_web/app.py", line 327, in create_combined_chart
    [charge_dates.dt.year.rename('year'),
  File "/home/cnhari/gps_tracker_web/venv/lib/python3.10/site-packages/pandas/core/generic.py", line 6299, in __getattr__
    return object.__getattribute__(self, name)
  File "/home/cnhari/gps_tracker_web/venv/lib/python3.10/site-packages/pandas/core/accessor.py", line 224, in __get__
    accessor_obj = self._accessor(obj)
  File "/home/cnhari/gps_tracker_web/venv/lib/python3.10/site-packages/pandas/core/indexes/accessors.py", line 643, in __new__
    raise AttributeError("Can only use .dt accessor with datetimelike values")
AttributeError: Can only use .dt accessor with datetimelike values
2025-06-26 15:37:50,929 ERROR: Server Error: 500 Internal Server Error: The server encountered an internal error and was unable to complete your request. Either the server is overloaded or there is an error in the application. [in /home/cnhari/gps_tracker_web/app.py:1193]
2025-06-26 15:39:08,045 ERROR: Error creating combined chart: Can only use .dt accessor with datetimelike values [in /home/cnhari/gps_tracker_web/app.py:403]
